<?xml version="1.0" encoding="utf-8"?>
<!-- This URDF was automatically created by SolidWorks to URDF Exporter! Originally created by Stephen Brawner (brawner@gmail.com) 
     Commit Version: 1.5.1-0-g916b5db  Build Version: 1.5.7152.31018
     For more information, please see http://wiki.ros.org/sw_urdf_exporter -->
<robot
  name="robot_arm">
  <link name="world"/>
  <joint name="base_joint" type="fixed">
    <parent link="world"/>
    <child link="base_link"/>
    <origin rpy="0 0 0" xyz="0.0 0.0 0.0"/>
  </joint> 
  <link
    name="base_link">
    <inertial>
      <origin
        xyz="5.0209E-08 0.00012636 0.069544"
        rpy="0 0 0" />
      <mass
        value="1.3174" />
      <inertia
        ixx="0.0030694"
        ixy="-5.1941E-10"
        ixz="-4.6994E-09"
        iyy="0.0032541"
        iyz="-9.8315E-06"
        izz="0.001334" />
    </inertial>
    <visual>
      <origin
        xyz="0 0 0"
        rpy="0 0 0" />
      <geometry>
        <mesh
          filename="package://robot_arm/meshes/base_link.STL" />
      </geometry>
      <material
        name="">
        <color
          rgba="0.89804 0.91765 0.92941 1" />
      </material>
    </visual>
    <collision>
      <origin
        xyz="0 0 0"
        rpy="0 0 0" />
      <geometry>
        <mesh
          filename="package://robot_arm/meshes/base_link.STL" />
      </geometry>
      <surface>
        <contact>
          <ode>
            <min_depth>0.001</min_depth>
          </ode>
        </contact>
        <friction>
          <ode>
            <mu>10000</mu>
            <mu2>10000</mu2>
          </ode>
        </friction>
      </surface>
    </collision>
  </link>
  <link
    name="link1">
    <inertial>
      <origin
        xyz="-4.3764E-06 -6.9417E-14 0.018224"
        rpy="0 0 0" />
      <mass
        value="0.31325" />
      <inertia
        ixx="0.00048442"
        ixy="1.8327E-18"
        ixz="-1.378E-08"
        iyy="0.00049375"
        iyz="1.0078E-18"
        izz="0.00095151" />
    </inertial>
    <visual>
      <origin
        xyz="0 0 0"
        rpy="0 0 0" />
      <geometry>
        <mesh
          filename="package://robot_arm/meshes/link1.STL" />
      </geometry>
      <material
        name="">
        <color
          rgba="1 1 1 1" />
      </material>
    </visual>
    <collision>
      <origin
        xyz="0 0 0"
        rpy="0 0 0" />
      <geometry>
        <mesh
          filename="package://robot_arm/meshes/link1.STL" />
      </geometry>
      <surface>
        <contact>
          <ode>
            <min_depth>0.001</min_depth>
          </ode>
        </contact>
        <friction>
          <ode>
            <mu>10000</mu>
            <mu2>10000</mu2>
          </ode>
        </friction>
      </surface>
    </collision>
  </link>
  <joint
    name="joint_1"
    type="revolute">
    <origin
      xyz="0 0 0.134"
      rpy="0 0 0" />
    <parent
      link="base_link" />
    <child
      link="link1" />
    <axis
      xyz="0 0 1" />
    <limit
      lower="0"
      upper="3.14"
      effort="200"
      velocity="3" />
  </joint>
  <link
    name="link2">
    <inertial>
      <origin
        xyz="-0.0023684 0.082679 -0.012795"
        rpy="0 0 0" />
      <mass
        value="0.15073" />
      <inertia
        ixx="0.00047271"
        ixy="9.7164E-06"
        ixz="-9.0217E-06"
        iyy="0.0002799"
        iyz="6.7422E-05"
        izz="0.00023406" />
    </inertial>
    <visual>
      <origin
        xyz="0 0 0"
        rpy="0 0 0" />
      <geometry>
        <mesh
          filename="package://robot_arm/meshes/link2.STL" />
      </geometry>
      <material
        name="">
        <color
          rgba="1 1 1 1" />
      </material>
    </visual>
    <collision>
      <origin
        xyz="0 0 0"
        rpy="0 0 0" />
      <geometry>
        <mesh
          filename="package://robot_arm/meshes/link2.STL" />
      </geometry>
      <surface>
        <contact>
          <ode>
            <min_depth>0.001</min_depth>
          </ode>
        </contact>
        <friction>
          <ode>
            <mu>10000</mu>
            <mu2>10000</mu2>
          </ode>
        </friction>
      </surface>
    </collision>
  </link>
  <joint
    name="joint_2"
    type="revolute">
    <origin
      xyz="0 0 0.0485"
      rpy="1.5708 0 1.5708" />
    <parent
      link="link1" />
    <child
      link="link2" />
    <axis
      xyz="0 0 -1" />
    <limit
      lower="-1.57"
      upper="1.57"
      effort="200"
      velocity="3" />
  </joint>
  <link
    name="link3">
    <inertial>
      <origin
        xyz="0.071288 0.0027817 -0.0024319"
        rpy="0 0 0" />
      <mass
        value="0.12674" />
      <inertia
        ixx="0.00012046"
        ixy="-6.9257E-06"
        ixz="1.879E-05"
        iyy="0.00023578"
        iyz="2.8516E-06"
        izz="0.00015143" />
    </inertial>
    <visual>
      <origin
        xyz="0 0 0"
        rpy="0 0 0" />
      <geometry>
        <mesh
          filename="package://robot_arm/meshes/link3.STL" />
      </geometry>
      <material
        name="">
        <color
          rgba="1 1 1 1" />
      </material>
    </visual>
    <collision>
      <origin
        xyz="0 0 0"
        rpy="0 0 0" />
      <geometry>
        <mesh
          filename="package://robot_arm/meshes/link3.STL" />
      </geometry>
      <surface>
        <contact>
          <ode>
            <min_depth>0.001</min_depth>
          </ode>
        </contact>
        <friction>
          <ode>
            <mu>10000</mu>
            <mu2>10000</mu2>
          </ode>
        </friction>
      </surface>
    </collision>
  </link>
  <joint
    name="joint_3"
    type="revolute">
    <origin
      xyz="-0.0010291 0.12402 0"
      rpy="0 0 1.5708" />
    <parent
      link="link2" />
    <child
      link="link3" />
    <axis
      xyz="0 0 1" />
    <limit
      lower="-1.57"
      upper="1.57"
      effort="200"
      velocity="3" />
  </joint>
  <link
    name="link4">
    <inertial>
      <origin
        xyz="0.055765 -7.1787E-07 0.00030886"
        rpy="0 0 0" />
      <mass
        value="0.06016" />
      <inertia
        ixx="7.1743E-05"
        ixy="3.2607E-11"
        ixz="9.4983E-07"
        iyy="0.00012402"
        iyz="-2.0369E-09"
        izz="5.8439E-05" />
    </inertial>
    <visual>
      <origin
        xyz="0 0 0"
        rpy="0 0 0" />
      <geometry>
        <mesh
          filename="package://robot_arm/meshes/link4.STL" />
      </geometry>
      <material
        name="">
        <color
          rgba="1 1 1 1" />
      </material>
    </visual>
    <collision>
      <origin
        xyz="0 0 0"
        rpy="0 0 0" />
      <geometry>
        <mesh
          filename="package://robot_arm/meshes/link4.STL" />
      </geometry>
      <surface>
        <contact>
          <ode>
            <min_depth>0.001</min_depth>
          </ode>
        </contact>
        <friction>
          <ode>
            <mu>10000</mu>
            <mu2>10000</mu2>
          </ode>
        </friction>
      </surface>
    </collision>
  </link>
  <joint
    name="joint_4"
    type="revolute">
    <origin
      xyz="0.10496 0.0011351 0"
      rpy="0 0 0" />
    <parent
      link="link3" />
    <child
      link="link4" />
    <axis
      xyz="0 0 1" />
    <limit
      lower="-1.57"
      upper="1.57"
      effort="200"
      velocity="3" />
  </joint>
  <link
    name="gripper_right">
    <inertial>
      <origin
        xyz="-0.0031855 -0.0022845 -0.027357"
        rpy="0 0 0" />
      <mass
        value="0.0089859" />
      <inertia
        ixx="2.1201E-06"
        ixy="-2.5369E-15"
        ixz="1.593E-15"
        iyy="1.9257E-06"
        iyz="-1.6346E-07"
        izz="2.0794E-07" />
    </inertial>
    <visual>
      <origin
        xyz="0 0 0"
        rpy="0 0 0" />
      <geometry>
        <mesh
          filename="package://robot_arm/meshes/gripper_right.STL" />
      </geometry>
      <material
        name="">
        <color
          rgba="0.89804 0.91765 0.92941 1" />
      </material>
    </visual>
    <collision>
      <origin
        xyz="0 0 0"
        rpy="0 0 0" />
      <geometry>
        <mesh
          filename="package://robot_arm/meshes/gripper_right.STL" />
      </geometry>
      <surface>
        <contact>
          <ode>
            <min_depth>0.001</min_depth>
          </ode>
        </contact>
        <friction>
          <ode>
            <mu>10000</mu>
            <mu2>10000</mu2>
          </ode>
        </friction>
      </surface>
    </collision>
  </link>
  <joint
    name="joint_5"
    type="revolute">
    <origin
      xyz="0.10888 0.001 -4.85E-05"
      rpy="1.7122 0 -1.5708" />
    <parent
      link="link4" />
    <child
      link="gripper_right" />
    <axis
      xyz="1 0 0" />
    <limit
      lower="0"
      upper="1.57"
      effort="200"
      velocity="3" />
  </joint>
  <link
    name="gripper_left">
    <inertial>
      <origin
        xyz="0.0031855 0.007424 -0.02643"
        rpy="0 0 0" />
      <mass
        value="0.0089859" />
      <inertia
        ixx="2.1201E-06"
        ixy="3.4201E-21"
        ixz="-2.4552E-21"
        iyy="1.8228E-06"
        iyz="4.3913E-07"
        izz="3.1081E-07" />
    </inertial>
    <visual>
      <origin
        xyz="0 0 0"
        rpy="0 0 0" />
      <geometry>
        <mesh
          filename="package://robot_arm/meshes/gripper_left.STL" />
      </geometry>
      <material
        name="">
        <color
          rgba="0.89804 0.91765 0.92941 1" />
      </material>
    </visual>
    <collision>
      <origin
        xyz="0 0 0"
        rpy="0 0 0" />
      <geometry>
        <mesh
          filename="package://robot_arm/meshes/gripper_left.STL" />
      </geometry>
      <surface>
        <contact>
          <ode>
            <min_depth>0.001</min_depth>
          </ode>
        </contact>
        <friction>
          <ode>
            <mu>10000</mu>
            <mu2>10000</mu2>
          </ode>
        </friction>
      </surface>
    </collision>
  </link>
  <joint
    name="joint_6"
    type="revolute">
    <origin
      xyz="0.10888 0.005 -4.85E-05"
      rpy="-1.7494 0 1.5708" />
    <parent
      link="link4" />
    <child
      link="gripper_left" />
    <axis
      xyz="-1 0 0" />
    <limit
      lower="-1.57"
      upper="0"
      effort="200"
      velocity="3" />
  </joint>

  <transmission name="link_1_trans">
    <type>transmission_interface/SimpleTransmission</type>
    <joint name="joint_1">
      <hardwareInterface>hardware_interface/PositionJointInterface</hardwareInterface>  
    </joint>
    <actuator name="link_1_motor">
      <hardwareInterface>hardware_interface/PositionJointInterface</hardwareInterface>
      <mechanicalReduction>1</mechanicalReduction>
    </actuator>
  </transmission>

  <transmission name="link_2_trans">
    <type>transmission_interface/SimpleTransmission</type>
    <joint name="joint_2">
      <hardwareInterface>hardware_interface/PositionJointInterface</hardwareInterface>  
    </joint>
    <actuator name="link_2_motor">
      <hardwareInterface>hardware_interface/PositionJointInterface</hardwareInterface>
      <mechanicalReduction>1</mechanicalReduction>
    </actuator>
  </transmission>

  <transmission name="link_3_trans">
    <type>transmission_interface/SimpleTransmission</type>
    <joint name="joint_3">
      <hardwareInterface>hardware_interface/PositionJointInterface</hardwareInterface>  
    </joint>
    <actuator name="link_3_motor">
      <hardwareInterface>hardware_interface/PositionJointInterface</hardwareInterface>
      <mechanicalReduction>1</mechanicalReduction>
    </actuator>
  </transmission>
  
  <transmission name="link_4_trans">
    <type>transmission_interface/SimpleTransmission</type>
    <joint name="joint_4">
      <hardwareInterface>hardware_interface/PositionJointInterface</hardwareInterface>  
    </joint>
    <actuator name="link_4_motor">
      <hardwareInterface>hardware_interface/PositionJointInterface</hardwareInterface>
      <mechanicalReduction>1</mechanicalReduction>
    </actuator>
  </transmission>

  <transmission name="gripper_right_trans">
    <type>transmission_interface/SimpleTransmission</type>
    <joint name="joint_5">
      <hardwareInterface>hardware_interface/PositionJointInterface</hardwareInterface>  
    </joint>
    <actuator name="gripper_right_motor">
      <hardwareInterface>hardware_interface/PositionJointInterface</hardwareInterface>
      <mechanicalReduction>1</mechanicalReduction>
    </actuator>
  </transmission>


  <transmission name="gripper_left_trans">
    <type>transmission_interface/SimpleTransmission</type>
    <joint name="joint_6">
      <hardwareInterface>hardware_interface/PositionJointInterface</hardwareInterface>  
    </joint>
    <actuator name="gripper_left_motor">
      <hardwareInterface>hardware_interface/PositionJointInterface</hardwareInterface>
      <mechanicalReduction>1</mechanicalReduction>
    </actuator>
  </transmission>

  <gazebo>
    <plugin name="control" 
    filename="libgazebo_ros_control.so">
    <robotNamespace>/</robotNamespace>
    </plugin>
  </gazebo>

  <gazebo reference="link1">
    <selfCollide>true</selfCollide>
  </gazebo>

  <gazebo reference="link2">
    <selfCollide>true</selfCollide>
  </gazebo>

  <gazebo reference="link3">
    <selfCollide>true</selfCollide>
  </gazebo>

  <gazebo reference="link4">
    <selfCollide>true</selfCollide>
  </gazebo>

  <gazebo reference="gripper_right">
    <selfCollide>true</selfCollide>
  </gazebo>

  <gazebo reference="gripper_left">
    <selfCollide>true</selfCollide>
  </gazebo>

</robot>
